<?xml version="1.0" ?>
<!-- =================================================================================== -->
<!-- |    This document was autogenerated by xacro from lbr4.urdf.xacro                | -->
<!-- |    EDITING THIS FILE BY HAND IS NOT RECOMMENDED                                 | -->
<!-- =================================================================================== -->
<robot name="lbr4" xmlns:controller="http://playerstage.sourceforge.net/gazebo/xmlschema/#controller" xmlns:interface="http://playerstage.sourceforge.net/gazebo/xmlschema/#interface" xmlns:sensor="http://playerstage.sourceforge.net/gazebo/xmlschema/#sensor" xmlns:xacro="http://www.ros.org/wiki/xacro">
  <!-- lbr4-->
  <selfCollide>true</selfCollide>
  <!-- materials for visualization -->
  <material name="color_0">
    <color rgba="1.0 0.423529411765 0.196078431373 1.0"/>
  </material>
  <material name="color_j1">
    <color rgba="1.0 0.423529411765 0.196078431373 1.0"/>
  </material>
  <material name="color_j2">
    <color rgba="1.0 0.423529411765 0.196078431373 1.0"/>
  </material>
  <material name="color_j3">
    <color rgba="1.0 0.423529411765 0.196078431373 1.0"/>
  </material>
  <material name="color_j4">
    <color rgba="1.0 0.423529411765 0.156862745098 1.0"/>
  </material>
  <material name="color_j5">
    <color rgba="1.0 0.423529411765 0.117647058824 1.0"/>
  </material>
  <material name="color_j6">
    <color rgba="1.0 0.423529411765 0.078431372549 1.0"/>
  </material>
  <material name="color_j7">
    <color rgba="1.0 0.423529411765 0.0392156862745 1.0"/>
  </material>
  <material name="Green">
    <color rgba="0.0 0.8 0.0 1.0"/>
  </material>
  <material name="Grey">
    <color rgba="0.7 0.7 0.7 1.0"/>
  </material>
  <material name="Grey2">
    <color rgba="0.9 0.9 0.9 1.0"/>
  </material>
  <material name="Red">
    <color rgba="0.8 0.5 0.5 1.0"/>
  </material>
  <material name="White">
    <color rgba="1.0 1.0 1.0 1.0"/>
  </material>
  <material name="Black">
    <color rgba="0.0 0.0 0.0 1.0"/>
  </material>
  <!-- world + base link-->
  <link name="base_link"/>
  <!--lbr4-->
  <xacro:property name="M_PI" value="3.1415926535897931"/>
  <!-- joint between {parent} and arm_0_link -->
  <joint name="base_link_base" type="fixed">
    <origin rpy="0 0 0" xyz="0 0 0.0"/>
    <parent link="base_link"/>
    <child link="lbr4_0_link"/>
  </joint>
  <link name="lbr4_0_link">
    <inertial>
      <origin rpy="0.503323678478 -0.189146421623 0.277526064738" xyz="0.0099787706820535227 -0.00048169854600738104 -0.25485509312792326"/>
      <mass value="1.5"/>
      <inertia ixx="0.00805112828804" ixy="0" ixz="0" iyy="0.00845152236845" iyz="0" izz="0.00863585824764"/>
    </inertial>
    <visual>
      <origin rpy="0 0 3.14159265359" xyz="0 0 0"/>
      <geometry>
        <mesh filename="package://ll4ma_robots_description/meshes/lbr4/link0.stl"/>
      </geometry>
      <material name="color_j1"/>
    </visual>
    <collision>
      <origin rpy="0 0 3.14159265359" xyz="0 0 0"/>
      <geometry>
        <mesh filename="package://ll4ma_robots_description/meshes/lbr4/link0.dae"/>
      </geometry>
    </collision>
  </link>
  <!-- joint between arm_0_link and arm_1_link -->
  <joint name="lbr4_j0" type="revolute">
    <parent link="lbr4_0_link"/>
    <child link="lbr4_1_link"/>
    <!--origin xyz="0 0 0.103" rpy="0 0 0" /-->
    <origin rpy="0 0 0" xyz="0 0 0.11"/>
    <axis xyz="0 0 1"/>
    <dynamics damping="5"/>
    <limit effort="176" lower="-2.96" upper="2.96" velocity="1.91"/>
  </joint>
  <link name="lbr4_1_link">
    <inertial>
      <origin rpy="0.239538165056 0.00537995201801 0.0492155584082" xyz="2.1826998880744087e-05 -0.021623840412335664 -0.07915171924289198"/>
      <mass value="1.5"/>
      <inertia ixx="0.0129545076394" ixy="0" ixz="0" iyy="0.0128178432409" iyz="0" izz="0.00442072765916"/>
    </inertial>
    <visual>
      <origin rpy="0 0 3.14159265359" xyz="0 0 0"/>
      <geometry>
        <mesh filename="package://ll4ma_robots_description/meshes/lbr4/link1.stl"/>
      </geometry>
      <material name="color_j1"/>
    </visual>
    <collision>
      <origin rpy="0 0 3.14159265359" xyz="0 0 0"/>
      <geometry>
        <mesh filename="package://ll4ma_robots_description/meshes/lbr4/link1.dae"/>
      </geometry>
    </collision>
  </link>
  <!-- joint between arm_1_link and arm_2_link -->
  <joint name="lbr4_j1" type="revolute">
    <parent link="lbr4_1_link"/>
    <child link="lbr4_2_link"/>
    <dynamics damping="5"/>
    <origin rpy="0 0 0" xyz="0 0 0.20"/>
    <!--origin xyz="0 0 0.2005" rpy="0 0 0"/-->
    <!--origin xyz="0 0 0.2105" rpy="0 0 0" /-->
    <axis xyz="0 -1 0"/>
    <limit effort="176" lower="-2.094" upper="2.094" velocity="1.91"/>
    <!--limit effort="1000" velocity="10" /-->
  </joint>
  <link name="lbr4_2_link">
    <inertial>
      <origin rpy="0.252444092172 -0.0167820344187 0.0575928285281" xyz="-0.0010097053542516513 0.028478464648332931 0.082033627936009448"/>
      <mass value="1.5"/>
      <inertia ixx="0.0132950018592" ixy="0" ixz="0" iyy="0.0131003199685" iyz="0" izz="0.0044657387969"/>
    </inertial>
    <visual>
      <origin rpy="0 0 3.14159265359" xyz="0 0 0"/>
      <geometry>
        <mesh filename="package://ll4ma_robots_description/meshes/lbr4/link2.stl"/>
      </geometry>
      <material name="color_j2"/>
    </visual>
    <collision>
      <origin rpy="0 0 3.14159265359" xyz="0 0 0"/>
      <geometry>
        <mesh filename="package://ll4ma_robots_description/meshes/lbr4/link2.dae"/>
      </geometry>
    </collision>
  </link>
  <!-- joint between arm_2_link and arm_3_link -->
  <joint name="lbr4_j2" type="revolute">
    <parent link="lbr4_2_link"/>
    <child link="lbr4_3_link"/>
    <dynamics damping="5"/>
    <origin rpy="0 0 0" xyz="0 0 0.192"/>
    <!-- <origin xyz="0 0 0.20" rpy="0 0 0.8" /> -->
    <axis xyz="0 0 1"/>
    <limit effort="100" lower="-2.96" upper="2.96" velocity="2.234"/>
  </joint>
  <link name="lbr4_3_link">
    <inertial>
      <origin rpy="-0.211279484805 -0.0186487662306 -0.00721347462905" xyz="-0.00068512472584392442 0.022787627643261723 -0.078806475454300237"/>
      <mass value="1.5"/>
      <inertia ixx="0.0127763513867" ixy="0" ixz="0" iyy="0.0128011372133" iyz="0" izz="0.0043627376553"/>
    </inertial>
    <visual>
      <origin rpy="0 0 3.14159265359" xyz="0 0 0"/>
      <geometry>
        <mesh filename="package://ll4ma_robots_description/meshes/lbr4/link3.stl"/>
      </geometry>
      <material name="color_j3"/>
    </visual>
    <collision>
      <origin rpy="0 0 3.14159265359" xyz="0 0 0"/>
      <geometry>
        <mesh filename="package://ll4ma_robots_description/meshes/lbr4/link3.dae"/>
      </geometry>
    </collision>
  </link>
  <!-- joint between arm_3_link and arm_4_link -->
  <joint name="lbr4_j3" type="revolute">
    <parent link="lbr4_3_link"/>
    <child link="lbr4_4_link"/>
    <dynamics damping="5"/>
    <!--origin xyz="0 0.003 0.21" rpy="0 0 0" /-->
    <origin rpy="0 0 0" xyz="0 0 0.20"/>
    <axis xyz="0 1 0"/>
    <limit effort="100" lower="-2.094" upper="2.094" velocity="2.234"/>
    <!--limit effort="1000" velocity="10" /-->
  </joint>
  <link name="lbr4_4_link">
    <inertial>
      <origin rpy="0.259090664398 -0.00225330262131 0.0469419954367" xyz="-0.00025120620404353643 0.027040543208881447 0.082599870266635594"/>
      <mass value="1.5"/>
      <inertia ixx="0.0132276730313" ixy="0" ixz="0" iyy="0.0130734228464" iyz="0" izz="0.00439977729281"/>
    </inertial>
    <visual>
      <origin rpy="0 0 3.14159265359" xyz="0 0 0"/>
      <geometry>
        <mesh filename="package://ll4ma_robots_description/meshes/lbr4/link4.stl"/>
      </geometry>
      <material name="color_j4"/>
    </visual>
    <collision>
      <origin rpy="0 0 3.14159265359" xyz="0 0 0"/>
      <geometry>
        <mesh filename="package://ll4ma_robots_description/meshes/lbr4/link4.dae"/>
      </geometry>
    </collision>
  </link>
  <!-- joint between arm_4_link and arm_5_link -->
  <joint name="lbr4_j4" type="revolute">
    <parent link="lbr4_4_link"/>
    <child link="lbr4_5_link"/>
    <dynamics damping="5"/>
    <!--origin xyz="0 0 0.193" rpy="0 0 0" /-->
    <origin rpy="0 0 0" xyz="0 0 0.20"/>
    <axis xyz="0 0 1"/>
    <limit effort="100" lower="-2.96" upper="2.96" velocity="3.56"/>
  </joint>
  <link name="lbr4_5_link">
    <inertial>
      <origin rpy="-0.399346437469 -0.0238815557936 0.011018430381" xyz="-7.2951660343995983e-05 0.034300558520003806 -0.082836449419419589"/>
      <mass value="1.5"/>
      <inertia ixx="0.0124407882151" ixy="0" ixz="0" iyy="0.0124710412724" iyz="0" izz="0.00438005667842"/>
    </inertial>
    <visual>
      <origin rpy="0 0 3.14159265359" xyz="0 0 0"/>
      <geometry>
        <mesh filename="package://ll4ma_robots_description/meshes/lbr4/link5.stl"/>
      </geometry>
      <material name="color_j5"/>
    </visual>
    <collision>
      <origin rpy="0 0 3.14159265359" xyz="0 0 0"/>
      <geometry>
        <mesh filename="package://ll4ma_robots_description/meshes/lbr4/link5.dae"/>
      </geometry>
    </collision>
  </link>
  <!-- joint between arm_5_link and arm_6_link -->
  <joint name="lbr4_j5" type="revolute">
    <parent link="lbr4_5_link"/>
    <child link="lbr4_6_link"/>
    <dynamics damping="5"/>
    <origin rpy="0 0 0" xyz="0 0 0.19"/>
    <!--origin xyz="0 0 0.2" rpy="0 0 0" /-->
    <axis xyz="0 -1 0"/>
    <limit effort="38" lower="-2.094" upper="2.094" velocity="3.211"/>
  </joint>
  <link name="lbr4_6_link">
    <inertial>
      <origin rpy="0.0273247151986 -0.416007068876 -0.06463859276" xyz="0.0033265785100209406 -0.00025060639771109469 0.0006250581115164501"/>
      <mass value="0.75"/>
      <inertia ixx="0.00284169077177" ixy="0" ixz="0" iyy="0.00298256896714" iyz="0" izz="0.00296892557443"/>
    </inertial>
    <visual>
      <origin rpy="0 0 3.14159265359" xyz="0 0 0"/>
      <geometry>
        <mesh filename="package://ll4ma_robots_description/meshes/lbr4/link6.stl"/>
      </geometry>
      <material name="color_j6"/>
    </visual>
    <collision>
      <origin rpy="0 0 3.14159265359" xyz="0 0 0"/>
      <geometry>
        <mesh filename="package://ll4ma_robots_description/meshes/lbr4/link6.dae"/>
      </geometry>
    </collision>
  </link>
  <!-- joint between arm_6_link and arm_7_link -->
  <joint name="lbr4_j6" type="revolute">
    <parent link="lbr4_6_link"/>
    <child link="lbr4_7_link"/>
    <dynamics damping="0"/>
    <origin rpy="0 0 0" xyz="0 0 0.078"/>
    <!--origin xyz="0 0 0.079" rpy="0 0 0" /-->
    <axis xyz="0 0 1"/>
    <limit effort="38" lower="-2.96" upper="2.96" velocity="3.21"/>
  </joint>
  <link name="lbr4_7_link">
    <inertial>
      <origin rpy="-0.00140457256351 -0.0113238487485 -0.621939623896" xyz="-1.0508863000830793e-05 0.00049391465901896074 0.062507829615577853"/>
      <mass value="0.075"/>
      <inertia ixx="5.81502716972e-05" ixy="0" ixz="0" iyy="5.84472283068e-05" iyz="0" izz="9.68983240391e-05"/>
    </inertial>
    <visual>
      <origin rpy="0 0 3.14159265359" xyz="0 0 0"/>
      <geometry>
        <mesh filename="package://ll4ma_robots_description/meshes/lbr4/link7.stl"/>
      </geometry>
      <material name="color_j7"/>
    </visual>
    <collision>
      <origin rpy="0 0 3.14159265359" xyz="0 0 0"/>
      <geometry>
        <mesh filename="package://ll4ma_robots_description/meshes/lbr4/link7.dae"/>
      </geometry>
    </collision>
  </link>
  <link name="lbr4_mount">
    <visual>
      <origin rpy="0 0 0" xyz="-0.0415 -0.0415 0.0"/>
      <geometry>
        <mesh filename="package://ll4ma_robots_description/meshes/mounts/kuka_mount.stl"/>
      </geometry>
      <material name="color_j7"/>
    </visual>
    <collision>
      <origin rpy="0 0 0" xyz="-0.0415 -0.0415 0.0"/>
      <geometry>
        <mesh filename="package://ll4ma_robots_description/meshes/mounts/kuka_mount.stl"/>
      </geometry>
    </collision>
  </link>
  <joint name="lb4_mount_joint" type="fixed">
    <origin rpy="-3.14159265359 0 0" xyz="0 0.0 0.015"/>
    <parent link="lbr4_7_link"/>
    <child link="lbr4_mount"/>
  </joint>
  <gazebo reference="lbr4_0_link">
    <material>Gazebo/Orange</material>
  </gazebo>
  <gazebo reference="lbr4_1_link">
    <material>Gazebo/Orange</material>
  </gazebo>
  <gazebo reference="lbr4_2_link">
    <material>Gazebo/Orange</material>
  </gazebo>
  <gazebo reference="lbr4_3_link">
    <material>Gazebo/Orange</material>
  </gazebo>
  <gazebo reference="lbr4_4_link">
    <material>Gazebo/Orange</material>
  </gazebo>
  <gazebo reference="lbr4_5_link">
    <material>Gazebo/Orange</material>
  </gazebo>
  <gazebo reference="lbr4_6_link">
    <material>Gazebo/Grey</material>
  </gazebo>
  <gazebo reference="lbr4_7_link">
    <material>Gazebo/Black</material>
  </gazebo>
  <!-- Tool macro -->
  <xacro:tool/>
</robot>
